Workbook

Sheet DashBoard Repair

Sheet Pivot
A1: ST/LT | B1: St | M1: ST/LT | N1: St
F2: ST/LT | G2: St
A3: Post.Date | B3: Sum of Qty (pcs) | C3: Sum of Tonase (Kg) | M3: Grade | N3: Sum of Unrestricted Kg
A4: 46266 | B4: 19264 | C4: 10238.681 | F4: Gudang | G4: Sum of Qty (pcs) | H4: Sum of Tonase (Kg) | M4: Grd C | N4: 70357.219
A5: 46267 | B5: 18118 | C5: 15313.105 | F5: Gd.01 | G5: 9264 | H5: 3860.242 | M5: Prime | N5: 583228.21
A6: 46268 | B6: 26362 | C6: 15162.753 | F6: Gd.05 | G6: 86312 | H6: 52629.631 | M6: Grand Total | N6: 653585.43
A7: 46269 | B7: 16105 | C7: 10113.394 | F7: Gd.13 | G7: 140287 | H7: 93754.404
A8: 46270 | B8: 15323 | C8: 7536.886 | F8: Grand Total | G8: 235863 | H8: 150244.28
A9: 46271 | B9: 8220 | C9: 5191.317
A10: 46272 | B10: 9437 | C10: 7381.46
A11: 46273 | B11: 15410 | C11: 6830.97
A12: 46274 | B12: 19033 | C12: 13826.146
A13: 46275 | B13: 19173 | C13: 16312.916 | M13: Tanggal | N13: Gudang | O13: Shift | P13: Sum of Jumlah Operator
A14: 46276 | B14: 22572 | C14: 14836.369 | M14: 46270 | P14: 10
A15: 46277 | B15: 15120 | C15: 7560.658 | N15: Gd 1 | P15: 1
A16: 46278 | B16: 457 | C16: 1390.725 | O16: 1 | P16: 1
A17: 46279 | B17: 16681 | C17: 7711.541 | N17: Gd 13 | P17: 5
A18: 46280 | B18: 14588 | C18: 10837.356 | O18: 1 | P18: 5
A19: Grand Total | B19: 235863 | C19: 150244.28 | N19: Gd 5 | P19: 4
O20: 1 | P20: 4
M21: Grand Total | P21: 10

Sheet Repair
A1: Plant | B1: Order | C1: Actual W.C. | D1: Post.Date | E1: NAME | F1: LENGTH SIDE | G1: WIDTH SIDE | H1: DIAM MM | I1: TEBAL | J1: PANJANG | K1: Work Centre | L1: Mvt | M1: SLOC | N1: BATCH | O1: GR Qty Pcs | P1: GI Qty Pcs | Q1: GR Base Unit | R1: GI Base Unit | S1: MATERIAL NUMBER | T1: % GR/GI | U1: SETL | V1: Entry Date | W1: Trans. Loc. | X1: User name | Y1: Material Doc. | Z1: Period Pst | AA1: Time of Entry | AB1: Cost Centre | AC1: Qty SETL | AD1: LABELID | AE1: Doc.Date | AF1: HEAT NO. | AG1: REMARK | AH1: XX | AI1: Panjang Pipa | AJ1: ST/LT | AK1: Gudang | AL1: Bulan | AM1: Tonase (Kg) | AN1: Qty (pcs)
A2: 1105 | B2: 500000434115 | C2: REP-501 | D2: 46266 | H2: 28,60 | I2: 1.5 | J2: 267,00mm | K2: REP-501 | L2: 261 | M2: 5E06 | N2: 5261725HEC | O2: 0 | P2: 966 | Q2: 0 | R2: 258.888 | S2: XCB10BCA0150+02670 | T2: 0 | U2: HADAD | V2: 46266 | W2: Handheld | X2: GUDANG05C | Y2: 4912230789 | Z2: 202609 | AA2: 0.7327662 | AB2: 1105421201 | AC2: 0 | AD2: 3001456582 | AE2: 46266 | AI2: =IF(MID(S2,14,1)="A",RIGHT(S2,4)/1,IF(MID(S2,13,1)="+",RIGHT(S2,5)/10,IF(MID(S2,13,1)="-",RIGHT(S2,5)/1))) -> 267 | AJ2: =IF(AI2<3000,"St","LT") -> St | AK2: =VLOOKUP(MID(M2,2,1),Sheet4!A:B,2,FALSE) -> Gd.05 | AL2: =TEXT(D2,"mmmm") -> September | AM2: =Q2 -> 0 | AN2: =O2 -> 0
A3: 1105 | B3: 500000434115 | C3: REP-501 | D3: 46266 | H3: 28,60 | I3: 1.5 | J3: 267,00mm | K3: REP-501 | L3: 262 | M3: 5E06 | N3: 5261725HEC | O3: 0 | P3: -666 | Q3: 0 | R3: -178.488 | S3: XCB10BCA0150+02670 | T3: 0 | U3: HADAD | V3: 46266 | W3: Handheld | X3: GUDANG05C | Y3: 4912230811 | Z3: 202609 | AA3: 0.73553241 | AB3: 1105421201 | AC3: 0 | AD3: 3001456582 | AE3: 46266 | AI3: =IF(MID(S3,14,1)="A",RIGHT(S3,4)/1,IF(MID(S3,13,1)="+",RIGHT(S3,5)/10,IF(MID(S3,13,1)="-",RIGHT(S3,5)/1))) -> 267 | AJ3: =IF(AI3<3000,"St","LT") -> St | AK3: =VLOOKUP(MID(M3,2,1),Sheet4!A:B,2,FALSE) -> Gd.05 | AL3: =TEXT(D3,"mmmm") -> September | AM3: =Q3 -> 0 | AN3: =O3 -> 0
A4: 1105 | B4: 500000434115 | C4: REP-501 | D4: 46266 | H4: 28,60 | I4: 1.5 | J4: 267,00mm | K4: REP-501 | L4: 101 | M4: 5E07 | N4: 5261725HEA | O4: 300 | P4: 0 | Q4: 80.4 | R4: 0 | S4: XCB10BCA0150+02670 | T4: 0 | U4: HADAD | V4: 46266 | W4: Handheld | X4: GUDANG05C | Y4: 5002102636 | Z4: 202609 | AA4: 0.73305556 | AB4: 1105421201 | AC4: 0 | AD4: 3001456596 | AE4: 46266 | AI4: =IF(MID(S4,14,1)="A",RIGHT(S4,4)/1,IF(MID(S4,13,1)="+",RIGHT(S4,5)/10,IF(MID(S4,13,1)="-",RIGHT(S4,5)/1))) -> 267 | AJ4: =IF(AI4<3000,"St","LT") -> St | AK4: =VLOOKUP(MID(M4,2,1),Sheet4!A:B,2,FALSE) -> Gd.05 | AL4: =TEXT(D4,"mmmm") -> September | AM4: =Q4 -> 80.4 | AN4: =O4 -> 300
A5: 1105 | B5: 500000434614 | C5: REP-501 | D5: 46266 | H5: 50,80 | I5: 2.8 | J5: 388,00mm | K5: REP-501 | L5: 262 | M5: 5M08 | N5: 5261787HGC | O5: 0 | P5: -532 | Q5: 0 | R5: -684.152 | S5: YBB10CAA0280+03880 | T5: 0 | U5: WHKARU_SUHAR | V5: 46266 | W5: Desktop | X5: GUDANGADM02 | Y5: 4912229845 | Z5: 202609 | AA5: 0.64542824 | AB5: 1105421201 | AC5: 0 | AD5: 3001452701 | AE5: 46266 | AF5: - | AG5: PT. CHANDRA NUG | AI5: =IF(MID(S5,14,1)="A",RIGHT(S5,4)/1,IF(MID(S5,13,1)="+",RIGHT(S5,5)/10,IF(MID(S5,13,1)="-",RIGHT(S5,5)/1))) -> 388 | AJ5: =IF(AI5<3000,"St","LT") -> St | AK5: =VLOOKUP(MID(M5,2,1),Sheet4!A:B,2,FALSE) -> Gd.13 | AL5: =TEXT(D5,"mmmm") -> September | AM5: =Q5 -> 0 | AN5: =O5 -> 0
A6: 1105 | B6: 500000438000 | C6: REP-501 | D6: 46266 | H6: 50,80 | I6: 2.9 | J6: 384,00mm | K6: REP-501 | L6: 261 | M6: 5M08 | N6: 5261165HGC | O6: 0 | P6: 60 | Q6: 0 | R6: 78.9 | S6: YEB12CAA0290+03840 | T6: 0 | V6: 46266 | W6: Handheld | X6: GUDANG13C | Y6: 4912232002 | Z6: 202609 | AA6: 0.91601852 | AB6: 1105421201 | AC6: 0 | AD6: 4002013148 | AE6: 46266 | AI6: =IF(MID(S6,14,1)="A",RIGHT(S6,4)/1,IF(MID(S6,13,1)="+",RIGHT(S6,5)/10,IF(MID(S6,13,1)="-",RIGHT(S6,5)/1))) -> 384 | AJ6: =IF(AI6<3000,"St","LT") -> St | AK6: =VLOOKUP(MID(M6,2,1),Sheet4!A:B,2,FALSE) -> Gd.13 | AL6: =TEXT(D6,"mmmm") -> September | AM6: =Q6 -> 0 | AN6: =O6 -> 0
A7: 1105 | B7: 500000438000 | C7: REP-501 | D7: 46266 | H7: 50,80 | I7: 2.9 | J7: 384,00mm | K7: REP-501 | L7: 261 | M7: 5M08 | N7: 5261165HGC | O7: 0 | P7: 60 | Q7: 0 | R7: 78.9 | S7: YEB12CAA0290+03840 | T7: 0 | V7: 46266 | W7: Handheld | X7: GUDANG13C | Y7: 4912232003 | Z7: 202609 | AA7: 0.91648148 | AB7: 1105421201 | AC7: 0 | AD7: 4001995355 | AE7: 46266 | AI7: =IF(MID(S7,14,1)="A",RIGHT(S7,4)/1,IF(MID(S7,13,1)="+",RIGHT(S7,5)/10,IF(MID(S7,13,1)="-",RIGHT(S7,5)/1))) -> 384 | AJ7: =IF(AI7<3000,"St","LT") -> St | AK7: =VLOOKUP(MID(M7,2,1),Sheet4!A:B,2,FALSE) -> Gd.13 | AL7: =TEXT(D7,"mmmm") -> September | AM7: =Q7 -> 0 | AN7: =O7 -> 0
A8: 1105 | B8: 500000438000 | C8: REP-501 | D8: 46266 | E8: PT ASTEMO BEKASI MANUFACTURING | H8: 50,80 | I8: 2.9 | J8: 384,00mm | K8: REP-501 | L8: 101 | M8: 5M08 | N8: 5261165HGA | O8: 60 | P8: 0 | Q8: 78.9 | R8: 0 | S8: YEB12CAA0290+03840 | T8: 0 | V8: 46266 | W8: Handheld | X8: GUDANG13C | Y8: 5002102880 | Z8: 202609 | AA8: 0.91702546 | AB8: 1105421201 | AC8: 0 | AD8: 4002146875 | AE8: 46266 | AI8: =IF(MID(S8,14,1)="A",RIGHT(S8,4)/1,IF(MID(S8,13,1)="+",RIGHT(S8,5)/10,IF(MID(S8,13,1)="-",RIGHT(S8,5)/1))) -> 384 | AJ8: =IF(AI8<3000,"St","LT") -> St | AK8: =VLOOKUP(MID(M8,2,1),Sheet4!A:B,2,FALSE) -> Gd.13 | AL8: =TEXT(D8,"mmmm") -> September | AM8: =Q8 -> 78.9 | AN8: =O8 -> 60
A9: 1105 | B9: 500000438000 | C9: REP-501 | D9: 46266 | E9: PT ASTEMO BEKASI MANUFACTURING | H9: 50,80 | I9: 2.9 | J9: 384,00mm | K9: REP-501 | L9: 101 | M9: 5M08 | N9: 5261165HGA | O9: 60 | P9: 0 | Q9: 78.9 | R9: 0 | S9: YEB12CAA0290+03840 | T9: 0 | V9: 46266 | W9: Handheld | X9: GUDANG13C | Y9: 5002102880 | Z9: 202609 | AA9: 0.91702546 | AB9: 1105421201 | AC9: 0 | AD9: 4002146876 | AE9: 46266 | AI9: =IF(MID(S9,14,1)="A",RIGHT(S9,4)/1,IF(MID(S9,13,1)="+",RIGHT(S9,5)/10,IF(MID(S9,13,1)="-",RIGHT(S9,5)/1))) -> 384 | AJ9: =IF(AI9<3000,"St","LT") -> St | AK9: =VLOOKUP(MID(M9,2,1),Sheet4!A:B,2,FALSE) -> Gd.13 | AL9: =TEXT(D9,"mmmm") -> September | AM9: =Q9 -> 78.9 | AN9: =O9 -> 60
A10: 1105 | B10: 500000438000 | C10: REP-501 | D10: 46266 | E10: PT ASTEMO BEKASI MANUFACTURING | H10: 50,80 | I10: 2.9 | J10: 384,00mm | K10: REP-501 | L10: 101 | M10: 5M08 | N10: 5261165HGA | O10: 60 | P10: 0 | Q10: 78.9 | R10: 0 | S10: YEB12CAA0290+03840 | T10: 0 | V10: 46266 | W10: Handheld | X10: GUDANG13C | Y10: 5002102855 | Z10: 202609 | AA10: 0.87983796 | AB10: 1105421201 | AC10: 0 | AD10: 4002146874 | AE10: 46266 | AI10: =IF(MID(S10,14,1)="A",RIGHT(S10,4)/1,IF(MID(S10,13,1)="+",RIGHT(S10,5)/10,IF(MID(S10,13,1)="-",RIGHT(S10,5)/1))) -> 384 | AJ10: =IF(AI10<3000,"St","LT") -> St | AK10: =VLOOKUP(MID(M10,2,1),Sheet4!A:B,2,FALSE) -> Gd.13 | AL10: =TEXT(D10,"mmmm") -> September | AM10: =Q10 -> 78.9 | AN10: =O10 -> 60
A11: 1105 | B11: 500000438000 | C11: REP-501 | D11: 46266 | E11: PT ASTEMO BEKASI MANUFACTURING | H11: 50,80 | I11: 2.9 | J11: 384,00mm | K11: REP-501 | L11: 101 | M11: 5M08 | N11: 5261165HGA | O11: 60 | P11: 0 | Q11: 78.9 | R11: 0 | S11: YEB12CAA0290+03840 | T11: 0 | V11: 46266 | W11: Handheld | X11: GUDANG13C | Y11: 5002102855 | Z11: 202609 | AA11: 0.87983796 | AB11: 1105421201 | AC11: 0 | AD11: 4002146873 | AE11: 46266 | AI11: =IF(MID(S11,14,1)="A",RIGHT(S11,4)/1,IF(MID(S11,13,1)="+",RIGHT(S11,5)/10,IF(MID(S11,13,1)="-",RIGHT(S11,5)/1))) -> 384 | AJ11: =IF(AI11<3000,"St","LT") -> St | AK11: =VLOOKUP(MID(M11,2,1),Sheet4!A:B,2,FALSE) -> Gd.13 | AL11: =TEXT(D11,"mmmm") -> September | AM11: =Q11 -> 78.9 | AN11: =O11 -> 60
A12: 1105 | B12: 500000438000 | C12: REP-501 | D12: 46266 | H12: 50,80 | I12: 2.9 | J12: 384,00mm | K12: REP-501 | L12: 261 | M12: 5M08 | N12: 5261165HGC | O12: 0 | P12: 60 | Q12: 0 | R12: 78.9 | S12: YEB12CAA0290+03840 | T12: 0 | V12: 46266 | W12: Handheld | X12: GUDANG13C | Y12: 4912231820 | Z12: 202609 | AA12: 0.87960648 | AB12: 1105421201 | AC12: 0 | AD12: 4002013147 | AE12: 46266 | AI12: =IF(MID(S12,14,1)="A",RIGHT(S12,4)/1,IF(MID(S12,13,1)="+",RIGHT(S12,5)/10,IF(MID(S12,13,1)="-",RIGHT(S12,5)/1))) -> 384 | AJ12: =IF(AI12<3000,"St","LT") -> St | AK12: =VLOOKUP(MID(M12,2,1),Sheet4!A:B,2,FALSE) -> Gd.13 | AL12: =TEXT(D12,"mmmm") -> September | AM12: =Q12 -> 0 | AN12: =O12 -> 0
A13: 1105 | B13: 500000438000 | C13: REP-501 | D13: 46266 | H13: 50,80 | I13: 2.9 | J13: 384,00mm | K13: REP-501 | L13: 261 | M13: 5M08 | N13: 5261165HGC | O13: 0 | P13: 60 | Q13: 0 | R13: 78.9 | S13: YEB12CAA0290+03840 | T13: 0 | V13: 46266 | W13: Handheld | X13: GUDANG13C | Y13: 4912231809 | Z13: 202609 | AA13: 0.87945602 | AB13: 1105421201 | AC13: 0 | AD13: 4001995356 | AE13: 46266 | AI13: =IF(MID(S13,14,1)="A",RIGHT(S13,4)/1,IF(MID(S13,13,1)="+",RIGHT(S13,5)/10,IF(MID(S13,13,1)="-",RIGHT(S13,5)/1))) -> 384 | AJ13: =IF(AI13<3000,"St","LT") -> St | AK13: =VLOOKUP(MID(M13,2,1),Sheet4!A:B,2,FALSE) -> Gd.13 | AL13: =TEXT(D13,"mmmm") -> September | AM13: =Q13 -> 0 | AN13: =O13 -> 0
A14: 1105 | B14: 500000438014 | C14: REP-501 | D14: 46266 | H14: 25,40 | I14: 0.6 | J14: 230,00mm | K14: REP-501 | L14: 261 | M14: 5M08 | N14: 5250628S0C | O14: 0 | P14: 12 | Q14: 0 | R14: 1.008 | S14: X1B12BAA0060+02300 | T14: 0 | U14: OBORGUDANG13 | V14: 46266 | W14: Handheld | X14: GUDANG13C | Y14: 4912231418 | Z14: 202609 | AA14: 0.82055556 | AB14: 1105421201 | AC14: 0 | AD14: 4001947985 | AE14: 46266 | AI14: =IF(MID(S14,14,1)="A",RIGHT(S14,4)/1,IF(MID(S14,13,1)="+",RIGHT(S14,5)/10,IF(MID(S14,13,1)="-",RIGHT(S14,5)/1))) -> 230 | AJ14: =IF(AI14<3000,"St","LT") -> St | AK14: =VLOOKUP(MID(M14,2,1),Sheet4!A:B,2,FALSE) -> Gd.13 | AL14: =TEXT(D14,"mmmm") -> September | AM14: =Q14 -> 0 | AN14: =O14 -> 0
A15: 1105 | B15: 500000438014 | C15: REP-501 | D15: 46266 | H15: 25,40 | I15: 0.6 | J15: 230,00mm | K15: REP-501 | L15: 261 | M15: 5M08 | N15: 5243254S0C | O15: 0 | P15: 68 | Q15: 0 | R15: 5.712 | S15: X1B12BAA0060+02300 | T15: 0 | U15: OBORGUDANG13 | V15: 46266 | W15: Handheld | X15: GUDANG13C | Y15: 4912231460 | Z15: 202609 | AA15: 0.82065972 | AB15: 1105421201 | AC15: 0 | AD15: 4001947984 | AE15: 46266 | AI15: =IF(MID(S15,14,1)="A",RIGHT(S15,4)/1,IF(MID(S15,13,1)="+",RIGHT(S15,5)/10,IF(MID(S15,13,1)="-",RIGHT(S15,5)/1))) -> 230 | AJ15: =IF(AI15<3000,"St","LT") -> St | AK15: =VLOOKUP(MID(M15,2,1),Sheet4!A:B,2,FALSE) -> Gd.13 | AL15: =TEXT(D15,"mmmm") -> September | AM15: =Q15 -> 0 | AN15: =O15 -> 0
A16: 1105 | B16: 500000438014 | C16: REP-501 | D16: 46266 | H16: 25,40 | I16: 0.6 | J16: 230,00mm | K16: REP-501 | L16: 261 | M16: 5M08 | N16: 5243254S0C | O16: 0 | P16: 80 | Q16: 0 | R16: 6.72 | S16: X1B12BAA0060+02300 | T16: 0 | U16: OBORGUDANG13 | V16: 46266 | W16: Handheld | X16: GUDANG13C | Y16: 4912231462 | Z16: 202609 | AA16: 0.8208912 | AB16: 1105421201 | AC16: 0 | AD16: 4001947982 | AE16: 46266 | AI16: =IF(MID(S16,14,1)="A",RIGHT(S16,4)/1,IF(MID(S16,13,1)="+",RIGHT(S16,5)/10,IF(MID(S16,13,1)="-",RIGHT(S16,5)/1))) -> 230 | AJ16: =IF(AI16<3000,"St","LT") -> St | AK16: =VLOOKUP(MID(M16,2,1),Sheet4!A:B,2,FALSE) -> Gd.13 | AL16: =TEXT(D16,"mmmm") -> September | AM16: =Q16 -> 0 | AN16: =O16 -> 0
A17: 1105 | B17: 500000438014 | C17: REP-501 | D17: 46266 | E17: PT ASTEMO BEKASI MANUFACTURING | H17: 25,40 | I17: 0.6 | J17: 230,00mm | K17: REP-501 | L17: 101 | M17: 5M08 | N17: 5243254S0A | O17: 43 | P17: 0 | Q17: 3.612 | R17: 0 | S17: X1B12BAA0060+02300 | T17: 0 | U17: OBORGUDANG13 | V17: 46266 | W17: Handheld | X17: GUDANG13C | Y17: 5002102816 | Z17: 202609 | AA17: 0.82118056 | AB17: 1105421201 | AC17: 0 | AD17: 4002147419 | AE17: 46266 | AI17: =IF(MID(S17,14,1)="A",RIGHT(S17,4)/1,IF(MID(S17,13,1)="+",RIGHT(S17,5)/10,IF(MID(S17,13,1)="-",RIGHT(S17,5)/1))) -> 230 | AJ17: =IF(AI17<3000,"St","LT") -> St | AK17: =VLOOKUP(MID(M17,2,1),Sheet4!A:B,2,FALSE) -> Gd.13 | AL17: =TEXT(D17,"mmmm") -> September | AM17: =Q17 -> 3.612 | AN17: =O17 -> 43
A18: 1105 | B18: 500000438014 | C18: REP-501 | D18: 46266 | E18: PT ASTEMO BEKASI MANUFACTURING | H18: 25,40 | I18: 0.6 | J18: 230,00mm | K18: REP-501 | L18: 101 | M18: 5M08 | N18: 5243254S0A | O18: 12 | P18: 0 | Q18: 1.008 | R18: 0 | S18: X1B12BAA0060+02300 | T18: 0 | U18: OBORGUDANG13 | V18: 46266 | W18: Handheld | X18: GUDANG13C | Y18: 5002102816 | Z18: 202609 | AA18: 0.82118056 | AB18: 1105421201 | AC18: 0 | AD18: 4002147420 | AE18: 46266 | AI18: =IF(MID(S18,14,1)="A",RIGHT(S18,4)/1,IF(MID(S18,13,1)="+",RIGHT(S18,5)/10,IF(MID(S18,13,1)="-",RIGHT(S18,5)/1))) -> 230 | AJ18: =IF(AI18<3000,"St","LT") -> St | AK18: =VLOOKUP(MID(M18,2,1),Sheet4!A:B,2,FALSE) -> Gd.13 | AL18: =TEXT(D18,"mmmm") -> September | AM18: =Q18 -> 1.008 | AN18: =O18 -> 12
A19: 1105 | B19: 500000438014 | C19: REP-501 | D19: 46266 | E19: PT ASTEMO BEKASI MANUFACTURING | H19: 25,40 | I19: 0.6 | J19: 230,00mm | K19: REP-501 | L19: 101 | M19: 5M08 | N19: 5243254S0A | O19: 57 | P19: 0 | Q19: 4.788 | R19: 0 | S19: X1B12BAA0060+02300 | T19: 0 | U19: OBORGUDANG13 | V19: 46266 | W19: Handheld | X19: GUDANG13C | Y19: 5002102816 | Z19: 202609 | AA19: 0.82118056 | AB19: 1105421201 | AC19: 0 | AD19: 4002147421 | AE19: 46266 | AI19: =IF(MID(S19,14,1)="A",RIGHT(S19,4)/1,IF(MID(S19,13,1)="+",RIGHT(S19,5)/10,IF(MID(S19,13,1)="-",RIGHT(S19,5)/1))) -> 230 | AJ19: =IF(AI19<3000,"St","LT") -> St | AK19: =VLOOKUP(MID(M19,2,1),Sheet4!A:B,2,FALSE) -> Gd.13 | AL19: =TEXT(D19,"mmmm") -> September | AM19: =Q19 -> 4.788 | AN19: =O19 -> 57
A20: 1105 | B20: 500000438214 | C20: REP-501 | D20: 46266 | E20: PT. TRIMITRA CHITRAHASTA | H20: 22,20 | I20: 1.9 | J20: 719,00mm | K20: REP-501 | L20: 101 | M20: 5M08 | N20: 5252082HIA | O20: 66 | P20: 0 | Q20: 45.144 | R20: 0 | S20: XCB12AOA0190+07190 | T20: 0 | V20: 46266 | W20: Handheld | X20: GUDANG13C | Y20: 5002102090 | Z20: 202609 | AA20: 0.54763889 | AB20: 1105421201 | AC20: 0 | AD20: 4002146562 | AE20: 46266 | AI20: =IF(MID(S20,14,1)="A",RIGHT(S20,4)/1,IF(MID(S20,13,1)="+",RIGHT(S20,5)/10,IF(MID(S20,13,1)="-",RIGHT(S20,5)/1))) -> 719 | AJ20: =IF(AI20<3000,"St","LT") -> St | AK20: =VLOOKUP(MID(M20,2,1),Sheet4!A:B,2,FALSE) -> Gd.13 | AL20: =TEXT(D20,"mmmm") -> September | AM20: =Q20 -> 45.144 | AN20: =O20 -> 66
A21: 1105 | B21: 500000438214 | C21: REP-501 | D21: 46266 | E21: PT. TRIMITRA CHITRAHASTA | H21: 22,20 | I21: 1.9 | J21: 719,00mm | K21: REP-501 | L21: 101 | M21: 5M08 | N21: 5252082HIA | O21: 10 | P21: 0 | Q21: 6.84 | R21: 0 | S21: XCB12AOA0190+07190 | T21: 0 | V21: 46266 | W21: Handheld | X21: GUDANG13C | Y21: 5002101914 | Z21: 202609 | AA21: 0.42423611 | AB21: 1105421201 | AC21: 0 | AD21: 4002146478 | AE21: 46266 | AI21: =IF(MID(S21,14,1)="A",RIGHT(S21,4)/1,IF(MID(S21,13,1)="+",RIGHT(S21,5)/10,IF(MID(S21,13,1)="-",RIGHT(S21,5)/1))) -> 719 | AJ21: =IF(AI21<3000,"St","LT") -> St | AK21: =VLOOKUP(MID(M21,2,1),Sheet4!A:B,2,FALSE) -> Gd.13 | AL21: =TEXT(D21,"mmmm") -> September | AM21: =Q21 -> 6.84 | AN21: =O21 -> 10
A22: 1105 | B22: 500000438214 | C22: REP-501 | D22: 46266 | E22: PT. TRIMITRA CHITRAHASTA | H22: 22,20 | I22: 1.9 | J22: 719,00mm | K22: REP-501 | L22: 101 | M22: 5M08 | N22: 5261756HIA | O22: 207 | P22: 0 | Q22: 141.588 | R22: 0 | S22: XCB12AOA0190+07190 | T22: 0 | V22: 46266 | W22: Handheld | X22: GUDANG13C | Y22: 5002101914 | Z22: 202609 | AA22: 0.42423611 | AB22: 1105421201 | AC22: 0 | AD22: 4002146477 | AE22: 46266 | AI22: =IF(MID(S22,14,1)="A",RIGHT(S22,4)/1,IF(MID(S22,13,1)="+",RIGHT(S22,5)/10,IF(MID(S22,13,1)="-",RIGHT(S22,5)/1))) -> 719 | AJ22: =IF(AI22<3000,"St","LT") -> St | AK22: =VLOOKUP(MID(M22,2,1),Sheet4!A:B,2,FALSE) -> Gd.13 | AL22: =TEXT(D22,"mmmm") -> September | AM22: =Q22 -> 141.588 | AN22: =O22 -> 207
A23: 1105 | B23: 500000438214 | C23: REP-501 | D23: 46266 | E23: PT. TRIMITRA CHITRAHASTA | H23: 22,20 | I23: 1.9 | J23: 719,00mm | K23: REP-501 | L23: 101 | M23: 5M08 | N23: 5261756HIA | O23: 217 | P23: 0 | Q23: 148.428 | R23: 0 | S23: XCB12AOA0190+07190 | T23: 0 | V23: 46266 | W23: Handheld | X23: GUDANG13C | Y23: 5002101914 | Z23: 202609 | AA23: 0.42423611 | AB23: 1105421201 | AC23: 0 | AD23: 4002146476 | AE23: 46266 | AI23: =IF(MID(S23,14,1)="A",RIGHT(S23,4)/1,IF(MID(S23,13,1)="+",RIGHT(S23,5)/10,IF(MID(S23,13,1)="-",RIGHT(S23,5)/1))) -> 719 | AJ23: =IF(AI23<3000,"St","LT") -> St | AK23: =VLOOKUP(MID(M23,2,1),Sheet4!A:B,2,FALSE) -> Gd.13 | AL23: =TEXT(D23,"mmmm") -> September | AM23: =Q23 -> 148.428 | AN23: =O23 -> 217
A24: 1105 | B24: 500000438214 | C24: REP-501 | D24: 46266 | H24: 22,20 | I24: 1.9 | J24: 719,00mm | K24: REP-501 | L24: 261 | M24: 5M08 | N24: 5252082HIC | O24: 0 | P24: 76 | Q24: 0 | R24: 51.984 | S24: XCB12AOA0190+07190 | T24: 0 | V24: 46266 | W24: Handheld | X24: GUDANG13C | Y24: 4912227311 | Z24: 202609 | AA24: 0.42349537 | AB24: 1105421201 | AC24: 0 | AD24: 4002019614 | AE24: 46266 | AI24: =IF(MID(S24,14,1)="A",RIGHT(S24,4)/1,IF(MID(S24,13,1)="+",RIGHT(S24,5)/10,IF(MID(S24,13,1)="-",RIGHT(S24,5)/1))) -> 719 | AJ24: =IF(AI24<3000,"St","LT") -> St | AK24: =VLOOKUP(MID(M24,2,1),Sheet4!A:B,2,FALSE) -> Gd.13 | AL24: =TEXT(D24,"mmmm") -> September | AM24: =Q24 -> 0 | AN24: =O24 -> 0
A25: 1105 | B25: 500000438214 | C25: REP-501 | D25: 46266 | H25: 22,20 | I25: 1.9 | J25: 719,00mm | K25: REP-501 | L25: 261 | M25: 5M08 | N25: 5261756HIC | O25: 0 | P25: 424 | Q25: 0 | R25: 290.016 | S25: XCB12AOA0190+07190 | T25: 0 | V25: 46266 | W25: Handheld | X25: GUDANG13C | Y25: 4912227286 | Z25: 202609 | AA25: 0.42090278 | AB25: 1105421201 | AC25: 0 | AD25: 4002146503 | AE25: 46266 | AI25: =IF(MID(S25,14,1)="A",RIGHT(S25,4)/1,IF(MID(S25,13,1)="+",RIGHT(S25,5)/10,IF(MID(S25,13,1)="-",RIGHT(S25,5)/1))) -> 719 | AJ25: =IF(AI25<3000,"St","LT") -> St | AK25: =VLOOKUP(MID(M25,2,1),Sheet4!A:B,2,FALSE) -> Gd.13 | AL25: =TEXT(D25,"mmmm") -> September | AM25: =Q25 -> 0 | AN25: =O25 -> 0
A26: 1105 | B26: 500000438228 | C26: REP-501 | D26: 46266 | E26: PT. KAYABA INDONESIA | H26: 53,00 | I26: 0.7 | J26: 177,00mm | K26: REP-501 | L26: 101 | M26: 5A11 | N26: 5251615L0A | O26: 50 | P26: 0 | Q26: 8 | R26: 0 | S26: X1B27CBG0070+01770 | T26: 0 | U26: OBOR | V26: 46266 | W26: Handheld | X26: GUDANG01B | Y26: 5002101982 | Z26: 202609 | AA26: 0.45283565 | AB26: 1105421201 | AC26: 0 | AD26: 4002146497 | AE26: 46266 | AI26: =IF(MID(S26,14,1)="A",RIGHT(S26,4)/1,IF(MID(S26,13,1)="+",RIGHT(S26,5)/10,IF(MID(S26,13,1)="-",RIGHT(S26,5)/1))) -> 177 | AJ26: =IF(AI26<3000,"St","LT") -> St | AK26: =VLOOKUP(MID(M26,2,1),Sheet4!A:B,2,FALSE) -> Gd.01 | AL26: =TEXT(D26,"mmmm") -> September | AM26: =Q26 -> 8 | AN26: =O26 -> 50
A27: 1105 | B27: 500000438228 | C27: REP-501 | D27: 46266 | E27: PT. KAYABA INDONESIA | H27: 53,00 | I27: 0.7 | J27: 177,00mm | K27: REP-501 | L27: 101 | M27: 5A11 | N27: 5251615L0A | O27: 50 | P27: 0 | Q27: 8 | R27: 0 | S27: X1B27CBG0070+01770 | T27: 0 | U27: OBOR | V27: 46266 | W27: Handheld | X27: GUDANG01B | Y27: 5002101982 | Z27: 202609 | AA27: 0.45283565 | AB27: 1105421201 | AC27: 0 | AD27: 4002146496 | AE27: 46266 | AI27: =IF(MID(S27,14,1)="A",RIGHT(S27,4)/1,IF(MID(S27,13,1)="+",RIGHT(S27,5)/10,IF(MID(S27,13,1)="-",RIGHT(S27,5)/1))) -> 177 | AJ27: =IF(AI27<3000,"St","LT") -> St | AK27: =VLOOKUP(MID(M27,2,1),Sheet4!A:B,2,FALSE) -> Gd.01 | AL27: =TEXT(D27,"mmmm") -> September | AM27: =Q27 -> 8 | AN27: =O27 -> 50
A28: 1105 | B28: 500000438228 | C28: REP-501 | D28: 46266 | H28: 53,00 | I28: 0.7 | J28: 177,00mm | K28: REP-501 | L28: 261 | M28: 5A06 | N28: 5251615L0C | O28: 0 | P28: 100 | Q28: 0 | R28: 16 | S28: X1B27CBG0070+01770 | T28: 0 | U28: 0BOR | V28: 46266 | W28: Handheld | X28: GUDANG01B | Y28: 4912227646 | Z28: 202609 | AA28: 0.45261574 | AB28: 1105421201 | AC28: 0 | AD28: 4001809198 | AE28: 46266 | AI28: =IF(MID(S28,14,1)="A",RIGHT(S28,4)/1,IF(MID(S28,13,1)="+",RIGHT(S28,5)/10,IF(MID(S28,13,1)="-",RIGHT(S28,5)/1))) -> 177 | AJ28: =IF(AI28<3000,"St","LT") -> St | AK28: =VLOOKUP(MID(M28,2,1),Sheet4!A:B,2,FALSE) -> Gd.01 | AL28: =TEXT(D28,"mmmm") -> September | AM28: =Q28 -> 0 | AN28: =O28 -> 0
A29: 1105 | B29: 500000438248 | C29: REP-501 | D29: 46266 | E29: PT. KAYABA INDONESIA | H29: 25,40 | I29: 0.5 | J29: 165,00mm | K29: REP-501 | L29: 101 | M29: 5M08 | N29: 5251263S0A | O29: 378 | P29: 0 | Q29: 19.278 | R29: 0 | S29: X1B12BAA0050+01650 | T29: 0 | V29: 46266 | W29: Handheld | X29: GUDANG13C | Y29: 5002102070 | Z29: 202609 | AA29: 0.53953704 | AB29: 1105421201 | AC29: 0 | AD29: 4002146540 | AE29: 46266 | AF29: SQ86126 | AI29: =IF(MID(S29,14,1)="A",RIGHT(S29,4)/1,IF(MID(S29,13,1)="+",RIGHT(S29,5)/10,IF(MID(S29,13,1)="-",RIGHT(S29,5)/1))) -> 165 | AJ29: =IF(AI29<3000,"St","LT") -> St | AK29: =VLOOKUP(MID(M29,2,1),Sheet4!A:B,2,FALSE) -> Gd.13 | AL29: =TEXT(D29,"mmmm") -> September | AM29: =Q29 -> 19.278 | AN29: =O29 -> 378
A30: 1105 | B30: 500000438248 | C30: REP-501 | D30: 46266 | E30: PT. KAYABA INDONESIA | H30: 25,40 | I30: 0.5 | J30: 165,00mm | K30: REP-501 | L30: 101 | M30: 5M08 | N30: 5251263S0A | O30: 100 | P30: 0 | Q30: 5.1 | R30: 0 | S30: X1B12BAA0050+01650 | T30: 0 | V30: 46266 | W30: Handheld | X30: GUDANG13C | Y30: 5002102070 | Z30: 202609 | AA30: 0.53953704 | AB30: 1105421201 | AC30: 0 | AD30: 4002146541 | AE30: 46266 | AF30: SQ86126 | AI30: =IF(MID(S30,14,1)="A",RIGHT(S30,4)/1,IF(MID(S30,13,1)="+",RIGHT(S30,5)/10,IF(MID(S30,13,1)="-",RIGHT(S30,5)/1))) -> 165 | AJ30: =IF(AI30<3000,"St","LT") -> St | AK30: =VLOOKUP(MID(M30,2,1),Sheet4!A:B,2,FALSE) -> Gd.13 | AL30: =TEXT(D30,"mmmm") -> September | AM30: =Q30 -> 5.1 | AN30: =O30 -> 100
A31: 1105 | B31: 500000438248 | C31: REP-501 | D31: 46266 | H31: 25,40 | I31: 0.5 | J31: 165,00mm | K31: REP-501 | L31: 261 | M31: 5M08 | N31: 5251263S0C | O31: 0 | P31: 922 | Q31: 0 | R31: 47.022 | S31: X1B12BAA0050+01650 | T31: 0 | V31: 46266 | W31: Handheld | X31: GUDANG13C | Y31: 4912228429 | Z31: 202609 | AA31: 0.5394213 | AB31: 1105421201 | AC31: 0 | AD31: 4002144394 | AE31: 46266 | AF31: SQ86126 | AI31: =IF(MID(S31,14,1)="A",RIGHT(S31,4)/1,IF(MID(S31,13,1)="+",RIGHT(S31,5)/10,IF(MID(S31,13,1)="-",RIGHT(S31,5)/1))) -> 165 | AJ31: =IF(AI31<3000,"St","LT") -> St | AK31: =VLOOKUP(MID(M31,2,1),Sheet4!A:B,2,FALSE) -> Gd.13 | AL31: =TEXT(D31,"mmmm") -> September | AM31: =Q31 -> 0 | AN31: =O31 -> 0
A32: 1105 | B32: 500000438276 | C32: REP-501 | D32: 46266 | E32: PT. CHANDRA NUGERAHCIPTA | H32: 15,90 | I32: 1.4 | J32: 100,00mm | K32: REP-501 | L32: 262 | M32: 5E08 | N32: 5241664D0C | O32: 0 | P32: -441 | Q32: 0 | R32: -22.05 | S32: X1B10AKA0140+01000 | T32: 0 | V32: 46266 | W32: Handheld | X32: GUDANG05B | Y32: 4912229529 | Z32: 202609 | AA32: 0.62121528 | AB32: 1105421201 | AC32: 0 | AD32: 3001455974 | AE32: 46266 | AF32: 24110001 | AG32: PT. CHANDRA NUG | AI32: =IF(MID(S32,14,1)="A",RIGHT(S32,4)/1,IF(MID(S32,13,1)="+",RIGHT(S32,5)/10,IF(MID(S32,13,1)="-",RIGHT(S32,5)/1))) -> 100 | AJ32: =IF(AI32<3000,"St","LT") -> St | AK32: =VLOOKUP(MID(M32,2,1),Sheet4!A:B,2,FALSE) -> Gd.05 | AL32: =TEXT(D32,"mmmm") -> September | AM32: =Q32 -> 0 | AN32: =O32 -> 0
A33: 1105 | B33: 500000438276 | C33: REP-501 | D33: 46266 | E33: PT. CHANDRA NUGERAHCIPTA | H33: 15,90 | I33: 1.4 | J33: 100,00mm | K33: REP-501 | L33: 101 | M33: 5E08 | N33: 5241664D0A | O33: 1540 | P33: 0 | Q33: 77 | R33: 0 | S33: X1B10AKA0140+01000 | T33: 0 | V33: 46266 | W33: Handheld | X33: GUDANG05B | Y33: 5002102271 | Z33: 202609 | AA33: 0.6208912 | AB33: 1105421201 | AC33: 0 | AD33: 3001456064 | AE33: 46266 | AF33: 24110001 | AG33: PT. CHANDRA NUG | AI33: =IF(MID(S33,14,1)="A",RIGHT(S33,4)/1,IF(MID(S33,13,1)="+",RIGHT(S33,5)/10,IF(MID(S33,13,1)="-",RIGHT(S33,5)/1))) -> 100 | AJ33: =IF(AI33<3000,"St","LT") -> St | AK33: =VLOOKUP(MID(M33,2,1),Sheet4!A:B,2,FALSE) -> Gd.05 | AL33: =TEXT(D33,"mmmm") -> September | AM33: =Q33 -> 77 | AN33: =O33 -> 1540
A34: 1105 | B34: 500000438276 | C34: REP-501 | D34: 46266 | E34: PT. CHANDRA NUGERAHCIPTA | H34: 15,90 | I34: 1.4 | J34: 100,00mm | K34: REP-501 | L34: 261 | M34: 5E08 | N34: 5241664D0C | O34: 0 | P34: 981 | Q34: 0 | R34: 49.05 | S34: X1B10AKA0140+01000 | T34: 0 | V34: 46266 | W34: Handheld | X34: GUDANG05B | Y34: 4912229501 | Z34: 202609 | AA34: 0.61986111 | AB34: 1105421201 | AC34: 0 | AD34: 3001455974 | AE34: 46266 | AF34: 24110001 | AG34: PT. CHANDRA NUG | AI34: =IF(MID(S34,14,1)="A",RIGHT(S34,4)/1,IF(MID(S34,13,1)="+",RIGHT(S34,5)/10,IF(MID(S34,13,1)="-",RIGHT(S34,5)/1))) -> 100 | AJ34: =IF(AI34<3000,"St","LT") -> St | AK34: =VLOOKUP(MID(M34,2,1),Sheet4!A:B,2,FALSE) -> Gd.05 | AL34: =TEXT(D34,"mmmm") -> September | AM34: =Q34 -> 0 | AN34: =O34 -> 0
A35: 1105 | B35: 500000438276 | C35: REP-501 | D35: 46266 | E35: PT. CHANDRA NUGERAHCIPTA | H35: 15,90 | I35: 1.4 | J35: 100,00mm | K35: REP-501 | L35: 261 | M35: 5E08 | N35: 5241664D0C | O35: 0 | P35: 1000 | Q35: 0 | R35: 50 | S35: X1B10AKA0140+01000 | T35: 0 | V35: 46266 | W35: Handheld | X35: GUDANG05B | Y35: 4912229489 | Z35: 202609 | AA35: 0.61960648 | AB35: 1105421201 | AC35: 0 | AD35: 3001455975 | AE35: 46266 | AF35: 24110001 | AG35: PT. CHANDRA NUG | AI35: =IF(MID(S35,14,1)="A",RIGHT(S35,4)/1,IF(MID(S35,13,1)="+",RIGHT(S35,5)/10,IF(MID(S35,13,1)="-",RIGHT(S35,5)/1))) -> 100 | AJ35: =IF(AI35<3000,"St","LT") -> St | AK35: =VLOOKUP(MID(M35,2,1),Sheet4!A:B,2,FALSE) -> Gd.05 | AL35: =TEXT(D35,"mmmm") -> September | AM35: =Q35 -> 0 | AN35: =O35 -> 0
A36: 1105 | B36: 500000438279 | C36: REP-501 | D36: 46266 | H36: 31,80 | I36: 5.3 | J36: 292,00mm | K36: REP-501 | L36: 261 | M36: 5M08 | N36: 5262730X0C | O36: 0 | P36: 205 | Q36: 0 | R36: 207.255 | S36: XCB29BEA0530+02920 | T36: 0 | U36: MP02SUGENG | V36: 46266 | W36: Handheld | X36: GUDANG13C | Y36: 4912229404 | Z36: 202609 | AA36: 0.61534722 | AB36: 1105421201 | AC36: 0 | AD36: 4002135015 | AE36: 46266 | AF36: 36262493 | AI36: =IF(MID(S36,14,1)="A",RIGHT(S36,4)/1,IF(MID(S36,13,1)="+",RIGHT(S36,5)/10,IF(MID(S36,13,1)="-",RIGHT(S36,5)/1))) -> 292 | AJ36: =IF(AI36<3000,"St","LT") -> St | AK36: =VLOOKUP(MID(M36,2,1),Sheet4!A:B,2,FALSE) -> Gd.13 | AL36: =TEXT(D36,"mmmm") -> September | AM36: =Q36 -> 0 | AN36: =O36 -> 0
A37: 1105 | B37: 500000438279 | C37: REP-501 | D37: 46266 | E37: PT. MENARA TERUS MAKMUR | H37: 31,80 | I37: 5.3 | J37: 292,00mm | K37: REP-501 | L37: 101 | M37: 5M08 | N37: 5262730X0A | O37: 51 | P37: 0 | Q37: 51.561 | R37: 0 | S37: XCB29BEA0530+02920 | T37: 0 | U37: MP02SUGENG | V37: 46266 | W37: Handheld | X37: GUDANG13C | Y37: 5002102253 | Z37: 202609 | AA37: 0.61548611 | AB37: 1105421201 | AC37: 0 | AD37: 4002146554 | AE37: 46266 | AF37: 36262493 | AI37: =IF(MID(S37,14,1)="A",RIGHT(S37,4)/1,IF(MID(S37,13,1)="+",RIGHT(S37,5)/10,IF(MID(S37,13,1)="-",RIGHT(S37,5)/1))) -> 292 | AJ37: =IF(AI37<3000,"St","LT") -> St | AK37: =VLOOKUP(MID(M37,2,1),Sheet4!A:B,2,FALSE) -> Gd.13 | AL37: =TEXT(D37,"mmmm") -> September | AM37: =Q37 -> 51.561 | AN37: =O37 -> 51
A38: 1105 | B38: 500000438279 | C38: REP-501 | D38: 46266 | H38: 31,80 | I38: 5.3 | J38: 292,00mm | K38: REP-501 | L38: 262 | M38: 5M08 | N38: 5262730X0C | O38: 0 | P38: -154 | Q38: 0 | R38: -155.694 | S38: XCB29BEA0530+02920 | T38: 0 | U38: WHKARU_SUHAR | V38: 46266 | W38: Handheld | X38: GUDANG13C | Y38: 4912229407 | Z38: 202609 | AA38: 0.61570602 | AB38: 1105421201 | AC38: 0 | AD38: 4002135015 | AE38: 46266 | AF38: 36262493 | AI38: =IF(MID(S38,14,1)="A",RIGHT(S38,4)/1,IF(MID(S38,13,1)="+",RIGHT(S38,5)/10,IF(MID(S38,13,1)="-",RIGHT(S38,5)/1))) -> 292 | AJ38: =IF(AI38<3000,"St","LT") -> St | AK38: =VLOOKUP(MID(M38,2,1),Sheet4!A:B,2,FALSE) -> Gd.13 | AL38: =TEXT(D38,"mmmm") -> September | AM38: =Q38 -> 0 | AN38: =O38 -> 0
A39: 1105 | B39: 500000438280 | C39: REP-501 | D39: 46266 | E39: PT. DHARMA POLIMETAL TBK. | H39: 22,20 | I39: 1.2 | J39: 162,00mm | K39: REP-501 | L39: 262 | M39: 5M08 | N39: 5250678HLC | O39: 0 | P39: -1277 | Q39: 0 | R39: -128.977 | S39: XCB10AOA0120+01620 | T39: 0 | U39: WHKARU_SUHAR | V39: 46266 | W39: Handheld | X39: GUDANG13C | Y39: 4912229177 | Z39: 202609 | AA39: 0.59350694 | AB39: 1105421201 | AC39: 0 | AD39: 3001453739 | AE39: 46266 | AF39: SP04878 | AG39: PT. DHARMA POLI | AI39: =IF(MID(S39,14,1)="A",RIGHT(S39,4)/1,IF(MID(S39,13,1)="+",RIGHT(S39,5)/10,IF(MID(S39,13,1)="-",RIGHT(S39,5)/1))) -> 162 | AJ39: =IF(AI39<3000,"St","LT") -> St | AK39: =VLOOKUP(MID(M39,2,1),Sheet4!A:B,2,FALSE) -> Gd.13 | AL39: =TEXT(D39,"mmmm") -> September | AM39: =Q39 -> 0 | AN39: =O39 -> 0
A40: 1105 | B40: 500000438280 | C40: REP-501 | D40: 46266 | E40: PT. DHARMA POLIMETAL TBK. | H40: 22,20 | I40: 1.2 | J40: 162,00mm | K40: REP-501 | L40: 261 | M40: 5M08 | N40: 5250678HLC | O40: 0 | P40: 537 | Q40: 0 | R40: 54.237 | S40: XCB10AOA0120+01620 | T40: 0 | U40: OBORGUDANG13 | V40: 46266 | W40: Handheld | X40: GUDANG13C | Y40: 4912232062 | Z40: 202609 | AA40: 0.92318287 | AB40: 1105421201 | AC40: 0 | AD40: 3001453719 | AE40: 46266 | AF40: SP04878 | AG40: PT. DHARMA POLI | AI40: =IF(MID(S40,14,1)="A",RIGHT(S40,4)/1,IF(MID(S40,13,1)="+",RIGHT(S40,5)/10,IF(MID(S40,13,1)="-",RIGHT(S40,5)/1))) -> 162 | AJ40: =IF(AI40<3000,"St","LT") -> St | AK40: =VLOOKUP(MID(M40,2,1),Sheet4!A:B,2,FALSE) -> Gd.13 | AL40: =TEXT(D40,"mmmm") -> September | AM40: =Q40 -> 0 | AN40: =O40 -> 0
...

Sheet Stok Grade C
A1: SLOC | B1: Customer | C1: MATERIAL NUMBER | D1: DIAM " | E1: LENGTH SIDE | F1: WIDTH SIDE | G1: DIAM MM | H1: TEBAL | I1: PANJANG | J1: Unrestricted Pcs | K1: Unrestricted Kg | L1: BATCH | M1: NOMOR SO | N1: ITEM SO | O1: Requested deliv.date | P1: CUST.REMARK | Q1: Forecats Cust. | R1: PASM | S1: PASG | T1: BLOK STOK BOm | U1: XX | V1: Gudang | W1: Panjang Pipa | X1: ST/LT | Y1: Grade
A2: 5D14 | B2: PT. GLOBAL DIMENSI METALINDO | C2: X1B00AHJ0100+61300 | G2: 12,00 | H2: 1,00 | I2: 6.130,00mm | J2: 107 | K2: 177.941 | L2: 5261688F0A | N2: 0 | Q2: PT. GLOBAL DIMENSI METALINDO | R2: FAST | S2: PRIME | T2: 0 | V2: =VLOOKUP(MID(A2,2,1),Sheet4!A:B,2,FALSE) -> Gd.04 | W2: =IF(MID(C2,14,1)="A",RIGHT(C2,4)/1,IF(MID(C2,13,1)="+",RIGHT(C2,5)/10,IF(MID(C2,13,1)="-",RIGHT(C2,5)/1))) -> 6130 | X2: =IF(W2<3000,"St","LT") -> LT | Y2: =VLOOKUP(RIGHT(L2,1),Sheet4!F:G,2,FALSE) -> Prime
A3: 5D27 | B3: PT. GLOBAL DIMENSI METALINDO | C3: X1B00AHJ0100+61300 | G3: 12,00 | H3: 1,00 | I3: 6.130,00mm | J3: 132 | K3: 219.516 | L3: 5261688F0A | N3: 0 | Q3: PT. GLOBAL DIMENSI METALINDO | R3: FAST | S3: PRIME | T3: 0 | V3: =VLOOKUP(MID(A3,2,1),Sheet4!A:B,2,FALSE) -> Gd.04 | W3: =IF(MID(C3,14,1)="A",RIGHT(C3,4)/1,IF(MID(C3,13,1)="+",RIGHT(C3,5)/10,IF(MID(C3,13,1)="-",RIGHT(C3,5)/1))) -> 6130 | X3: =IF(W3<3000,"St","LT") -> LT | Y3: =VLOOKUP(RIGHT(L3,1),Sheet4!F:G,2,FALSE) -> Prime
A4: 5C08 | C4: X1B00AIA0050+53400 | D4: 1/2" | G4: 12,70 | H4: 0,50 | I4: 5.340,00mm | J4: 83 | K4: 66.649 | L4: 5252874F0A | N4: 0 | R4: FAST | S4: PRIME | T4: 0 | V4: =VLOOKUP(MID(A4,2,1),Sheet4!A:B,2,FALSE) -> Gd.03 | W4: =IF(MID(C4,14,1)="A",RIGHT(C4,4)/1,IF(MID(C4,13,1)="+",RIGHT(C4,5)/10,IF(MID(C4,13,1)="-",RIGHT(C4,5)/1))) -> 5340 | X4: =IF(W4<3000,"St","LT") -> LT | Y4: =VLOOKUP(RIGHT(L4,1),Sheet4!F:G,2,FALSE) -> Prime
A5: 5C06 | B5: PT. RINNAI INDONESIA | C5: X1B00AIA0080+49900 | D5: 1/2" | G5: 12,70 | H5: 0,80 | I5: 4.990,00mm | J5: 413 | K5: 483.623 | L5: 5262615F0A | N5: 0 | P5: 50/IX/2026 HASIL MAKRO NG(LANJUT CU | Q5: PT. RINNAI INDONESIA | R5: FAST | S5: PRIME | T5: 0 | V5: =VLOOKUP(MID(A5,2,1),Sheet4!A:B,2,FALSE) -> Gd.03 | W5: =IF(MID(C5,14,1)="A",RIGHT(C5,4)/1,IF(MID(C5,13,1)="+",RIGHT(C5,5)/10,IF(MID(C5,13,1)="-",RIGHT(C5,5)/1))) -> 4990 | X5: =IF(W5<3000,"St","LT") -> LT | Y5: =VLOOKUP(RIGHT(L5,1),Sheet4!F:G,2,FALSE) -> Prime
A6: 5C06 | B6: PT. RINNAI INDONESIA | C6: X1B00AIA0080+49900 | D6: 1/2" | G6: 12,70 | H6: 0,80 | I6: 4.990,00mm | J6: 1324 | K6: 1550.404 | L6: 6261568F0A | N6: 0 | Q6: PT. RINNAI INDONESIA | R6: FAST | S6: PRIME | T6: 0 | V6: =VLOOKUP(MID(A6,2,1),Sheet4!A:B,2,FALSE) -> Gd.03 | W6: =IF(MID(C6,14,1)="A",RIGHT(C6,4)/1,IF(MID(C6,13,1)="+",RIGHT(C6,5)/10,IF(MID(C6,13,1)="-",RIGHT(C6,5)/1))) -> 4990 | X6: =IF(W6<3000,"St","LT") -> LT | Y6: =VLOOKUP(RIGHT(L6,1),Sheet4!F:G,2,FALSE) -> Prime
A7: 5C06 | B7: PT. RINNAI INDONESIA | C7: X1B00AIA0080+49900 | D7: 1/2" | G7: 12,70 | H7: 0,80 | I7: 4.990,00mm | J7: 2626 | K7: 3075.046 | L7: 6261570F0A | N7: 0 | Q7: PT. RINNAI INDONESIA | R7: FAST | S7: PRIME | T7: 0 | V7: =VLOOKUP(MID(A7,2,1),Sheet4!A:B,2,FALSE) -> Gd.03 | W7: =IF(MID(C7,14,1)="A",RIGHT(C7,4)/1,IF(MID(C7,13,1)="+",RIGHT(C7,5)/10,IF(MID(C7,13,1)="-",RIGHT(C7,5)/1))) -> 4990 | X7: =IF(W7<3000,"St","LT") -> LT | Y7: =VLOOKUP(RIGHT(L7,1),Sheet4!F:G,2,FALSE) -> Prime
A8: 5C08 | B8: PT. RINNAI INDONESIA | C8: X1B00AIA0080+49900 | D8: 1/2" | G8: 12,70 | H8: 0,80 | I8: 4.990,00mm | J8: 67 | K8: 78.457 | L8: 6261568F0A | N8: 0 | Q8: PT. RINNAI INDONESIA | R8: FAST | S8: PRIME | T8: 0 | V8: =VLOOKUP(MID(A8,2,1),Sheet4!A:B,2,FALSE) -> Gd.03 | W8: =IF(MID(C8,14,1)="A",RIGHT(C8,4)/1,IF(MID(C8,13,1)="+",RIGHT(C8,5)/10,IF(MID(C8,13,1)="-",RIGHT(C8,5)/1))) -> 4990 | X8: =IF(W8<3000,"St","LT") -> LT | Y8: =VLOOKUP(RIGHT(L8,1),Sheet4!F:G,2,FALSE) -> Prime
A9: 5D27 | B9: PT. RINNAI INDONESIA | C9: X1B00AIA0080+49900 | D9: 1/2" | G9: 12,70 | H9: 0,80 | I9: 4.990,00mm | J9: 281 | K9: 329.051 | L9: 5262614F0A | N9: 0 | Q9: PT. RINNAI INDONESIA | R9: FAST | S9: PRIME | T9: 0 | V9: =VLOOKUP(MID(A9,2,1),Sheet4!A:B,2,FALSE) -> Gd.04 | W9: =IF(MID(C9,14,1)="A",RIGHT(C9,4)/1,IF(MID(C9,13,1)="+",RIGHT(C9,5)/10,IF(MID(C9,13,1)="-",RIGHT(C9,5)/1))) -> 4990 | X9: =IF(W9<3000,"St","LT") -> LT | Y9: =VLOOKUP(RIGHT(L9,1),Sheet4!F:G,2,FALSE) -> Prime
A10: 5D27 | B10: PT. RINNAI INDONESIA | C10: X1B00AIA0080+49900 | D10: 1/2" | G10: 12,70 | H10: 0,80 | I10: 4.990,00mm | J10: 121 | K10: 141.691 | L10: 5262615F0A | N10: 0 | Q10: PT. RINNAI INDONESIA | R10: FAST | S10: PRIME | T10: 0 | V10: =VLOOKUP(MID(A10,2,1),Sheet4!A:B,2,FALSE) -> Gd.04 | W10: =IF(MID(C10,14,1)="A",RIGHT(C10,4)/1,IF(MID(C10,13,1)="+",RIGHT(C10,5)/10,IF(MID(C10,13,1)="-",RIGHT(C10,5)/1))) -> 4990 | X10: =IF(W10<3000,"St","LT") -> LT | Y10: =VLOOKUP(RIGHT(L10,1),Sheet4!F:G,2,FALSE) -> Prime
A11: 5D29 | B11: PT. UTAMA RAYA MOTOR INDUSTRY | C11: X1B00AIA0080+60600 | D11: 1/2" | G11: 12,70 | H11: 0,80 | I11: 6.060,00mm | J11: 299 | K11: 425.477 | L11: 5262613F0A | N11: 0 | Q11: PT. UTAMA RAYA MOTOR INDUSTRY | R11: FAST | S11: PRIME | T11: 0 | V11: =VLOOKUP(MID(A11,2,1),Sheet4!A:B,2,FALSE) -> Gd.04 | W11: =IF(MID(C11,14,1)="A",RIGHT(C11,4)/1,IF(MID(C11,13,1)="+",RIGHT(C11,5)/10,IF(MID(C11,13,1)="-",RIGHT(C11,5)/1))) -> 6060 | X11: =IF(W11<3000,"St","LT") -> LT | Y11: =VLOOKUP(RIGHT(L11,1),Sheet4!F:G,2,FALSE) -> Prime
A12: 5C09 | B12: PT. RINNAI INDONESIA | C12: X1B00AIA0100+42900 | D12: 1/2" | G12: 12,70 | H12: 1,00 | I12: 4.290,00mm | J12: 135 | K12: 167.13 | L12: 5262834F0A | N12: 0 | Q12: PT. RINNAI INDONESIA | R12: FAST | S12: PRIME | T12: 0 | V12: =VLOOKUP(MID(A12,2,1),Sheet4!A:B,2,FALSE) -> Gd.03 | W12: =IF(MID(C12,14,1)="A",RIGHT(C12,4)/1,IF(MID(C12,13,1)="+",RIGHT(C12,5)/10,IF(MID(C12,13,1)="-",RIGHT(C12,5)/1))) -> 4290 | X12: =IF(W12<3000,"St","LT") -> LT | Y12: =VLOOKUP(RIGHT(L12,1),Sheet4!F:G,2,FALSE) -> Prime
A13: 5C10 | B13: PT. RINNAI INDONESIA | C13: X1B00AIA0100+42900 | D13: 1/2" | G13: 12,70 | H13: 1,00 | I13: 4.290,00mm | J13: 3073 | K13: 3804.374 | L13: 5262837F0A | N13: 0 | Q13: PT. RINNAI INDONESIA | R13: FAST | S13: PRIME | T13: 0 | V13: =VLOOKUP(MID(A13,2,1),Sheet4!A:B,2,FALSE) -> Gd.03 | W13: =IF(MID(C13,14,1)="A",RIGHT(C13,4)/1,IF(MID(C13,13,1)="+",RIGHT(C13,5)/10,IF(MID(C13,13,1)="-",RIGHT(C13,5)/1))) -> 4290 | X13: =IF(W13<3000,"St","LT") -> LT | Y13: =VLOOKUP(RIGHT(L13,1),Sheet4!F:G,2,FALSE) -> Prime
A14: 5C10 | B14: PT. RINNAI INDONESIA | C14: X1B00AIA0100+42900 | D14: 1/2" | G14: 12,70 | H14: 1,00 | I14: 4.290,00mm | J14: 331 | K14: 409.778 | L14: 5263236F0A | N14: 0 | Q14: PT. RINNAI INDONESIA | R14: FAST | S14: PRIME | T14: 0 | V14: =VLOOKUP(MID(A14,2,1),Sheet4!A:B,2,FALSE) -> Gd.03 | W14: =IF(MID(C14,14,1)="A",RIGHT(C14,4)/1,IF(MID(C14,13,1)="+",RIGHT(C14,5)/10,IF(MID(C14,13,1)="-",RIGHT(C14,5)/1))) -> 4290 | X14: =IF(W14<3000,"St","LT") -> LT | Y14: =VLOOKUP(RIGHT(L14,1),Sheet4!F:G,2,FALSE) -> Prime
A15: 5C10 | B15: PT. RINNAI INDONESIA | C15: X1B00AIA0100+42900 | D15: 1/2" | G15: 12,70 | H15: 1,00 | I15: 4.290,00mm | J15: 556 | K15: 688.328 | L15: 6261574F0A | N15: 0 | Q15: PT. RINNAI INDONESIA | R15: FAST | S15: PRIME | T15: 0 | V15: =VLOOKUP(MID(A15,2,1),Sheet4!A:B,2,FALSE) -> Gd.03 | W15: =IF(MID(C15,14,1)="A",RIGHT(C15,4)/1,IF(MID(C15,13,1)="+",RIGHT(C15,5)/10,IF(MID(C15,13,1)="-",RIGHT(C15,5)/1))) -> 4290 | X15: =IF(W15<3000,"St","LT") -> LT | Y15: =VLOOKUP(RIGHT(L15,1),Sheet4!F:G,2,FALSE) -> Prime
A16: 5D09 | B16: PT. RINNAI INDONESIA | C16: X1B00AIA0100+42900 | D16: 1/2" | G16: 12,70 | H16: 1,00 | I16: 4.290,00mm | J16: 461 | K16: 570.718 | L16: 5262836F0A | N16: 0 | Q16: PT. RINNAI INDONESIA | R16: FAST | S16: PRIME | T16: 0 | V16: =VLOOKUP(MID(A16,2,1),Sheet4!A:B,2,FALSE) -> Gd.04 | W16: =IF(MID(C16,14,1)="A",RIGHT(C16,4)/1,IF(MID(C16,13,1)="+",RIGHT(C16,5)/10,IF(MID(C16,13,1)="-",RIGHT(C16,5)/1))) -> 4290 | X16: =IF(W16<3000,"St","LT") -> LT | Y16: =VLOOKUP(RIGHT(L16,1),Sheet4!F:G,2,FALSE) -> Prime
A17: 5D09 | B17: PT. RINNAI INDONESIA | C17: X1B00AIA0100+42900 | D17: 1/2" | G17: 12,70 | H17: 1,00 | I17: 4.290,00mm | J17: 201 | K17: 248.838 | L17: 5262837F0A | N17: 0 | Q17: PT. RINNAI INDONESIA | R17: FAST | S17: PRIME | T17: 0 | V17: =VLOOKUP(MID(A17,2,1),Sheet4!A:B,2,FALSE) -> Gd.04 | W17: =IF(MID(C17,14,1)="A",RIGHT(C17,4)/1,IF(MID(C17,13,1)="+",RIGHT(C17,5)/10,IF(MID(C17,13,1)="-",RIGHT(C17,5)/1))) -> 4290 | X17: =IF(W17<3000,"St","LT") -> LT | Y17: =VLOOKUP(RIGHT(L17,1),Sheet4!F:G,2,FALSE) -> Prime
... A25: 5D11 | B25: PT. RINNAI INDONESIA | C25: X1B00AIA0100+55630 | D25: 1/2" | G25: 12,70 | H25: 1,00 | I25: 5.563,00mm | J25: 423 | K25: 678.915 | L25: 5262837F0A | N25: 0 | Q25: PT. RINNAI INDONESIA | R25: FAST | S25: PRIME | T25: 0 | V25: =VLOOKUP(MID(A25,2,1),Sheet4!A:B,2,FALSE) -> Gd.04 | W25: =IF(MID(C25,14,1)="A",RIGHT(C25,4)/1,IF(MID(C25,13,1)="+",RIGHT(C25,5)/10,IF(MID(C25,13,1)="-",RIGHT(C25,5)/1))) -> 5563 | X25: =IF(W25<3000,"St","LT") -> LT | Y25: =VLOOKUP(RIGHT(L25,1),Sheet4!F:G,2,FALSE) -> Prime
A26: 5D29 | C26: X1B00AIA0110+60600 | D26: 1/2" | G26: 12,70 | H26: 1,10 | I26: 6.060,00mm | J26: 22 | K26: 41.954 | L26: 5240948C0C | N26: 0 | P26: 261/XI/2025 KARAT LUAR | R26: FAST | S26: NON PRIME | T26: 0 | V26: =VLOOKUP(MID(A26,2,1),Sheet4!A:B,2,FALSE) -> Gd.04 | W26: =IF(MID(C26,14,1)="A",RIGHT(C26,4)/1,IF(MID(C26,13,1)="+",RIGHT(C26,5)/10,IF(MID(C26,13,1)="-",RIGHT(C26,5)/1))) -> 6060 | X26: =IF(W26<3000,"St","LT") -> LT | Y26: =VLOOKUP(RIGHT(L26,1),Sheet4!F:G,2,FALSE) -> Grd C
A27: 5D14 | B27: PT. PUTRABANGUN CITRAMANDIRI | C27: X1B00AIA0110+60600 | D27: 1/2" | G27: 12,70 | H27: 1,10 | I27: 6.060,00mm | J27: 140 | K27: 266.98 | L27: 5260248F0A | N27: 0 | Q27: PT. PUTRABANGUN CITRAMANDIRI | R27: FAST | S27: PRIME | T27: 0 | V27: =VLOOKUP(MID(A27,2,1),Sheet4!A:B,2,FALSE) -> Gd.04 | W27: =IF(MID(C27,14,1)="A",RIGHT(C27,4)/1,IF(MID(C27,13,1)="+",RIGHT(C27,5)/10,IF(MID(C27,13,1)="-",RIGHT(C27,5)/1))) -> 6060 | X27: =IF(W27<3000,"St","LT") -> LT | Y27: =VLOOKUP(RIGHT(L27,1),Sheet4!F:G,2,FALSE) -> Prime
A28: 5D15 | B28: PT. PUTRABANGUN CITRAMANDIRI | C28: X1B00AIA0110+60600 | D28: 1/2" | G28: 12,70 | H28: 1,10 | I28: 6.060,00mm | J28: 159 | K28: 303.213 | L28: 5260249F0A | N28: 0 | Q28: PT. PUTRABANGUN CITRAMANDIRI | R28: FAST | S28: PRIME | T28: 0 | V28: =VLOOKUP(MID(A28,2,1),Sheet4!A:B,2,FALSE) -> Gd.04 | W28: =IF(MID(C28,14,1)="A",RIGHT(C28,4)/1,IF(MID(C28,13,1)="+",RIGHT(C28,5)/10,IF(MID(C28,13,1)="-",RIGHT(C28,5)/1))) -> 6060 | X28: =IF(W28<3000,"St","LT") -> LT | Y28: =VLOOKUP(RIGHT(L28,1),Sheet4!F:G,2,FALSE) -> Prime
A29: 5D15 | B29: PT. PUTRABANGUN CITRAMANDIRI | C29: X1B00AIA0110+60600 | D29: 1/2" | G29: 12,70 | H29: 1,10 | I29: 6.060,00mm | J29: 106 | K29: 202.142 | L29: 5260250F0A | N29: 0 | Q29: PT. PUTRABANGUN CITRAMANDIRI | R29: FAST | S29: PRIME | T29: 0 | V29: =VLOOKUP(MID(A29,2,1),Sheet4!A:B,2,FALSE) -> Gd.04 | W29: =IF(MID(C29,14,1)="A",RIGHT(C29,4)/1,IF(MID(C29,13,1)="+",RIGHT(C29,5)/10,IF(MID(C29,13,1)="-",RIGHT(C29,5)/1))) -> 6060 | X29: =IF(W29<3000,"St","LT") -> LT | Y29: =VLOOKUP(RIGHT(L29,1),Sheet4!F:G,2,FALSE) -> Prime
A30: 5C10 | B30: PT. GOLDEN AGIN NUSA | C30: X1B00AIA0120+52000 | D30: 1/2" | G30: 12,70 | H30: 1,20 | I30: 5.200,00mm | J30: 303 | K30: 536.31 | L30: 5261645F0A | N30: 0 | Q30: PT. GOLDEN AGIN NUSA | R30: FAST | S30: PRIME | T30: 0 | V30: =VLOOKUP(MID(A30,2,1),Sheet4!A:B,2,FALSE) -> Gd.03 | W30: =IF(MID(C30,14,1)="A",RIGHT(C30,4)/1,IF(MID(C30,13,1)="+",RIGHT(C30,5)/10,IF(MID(C30,13,1)="-",RIGHT(C30,5)/1))) -> 5200 | X30: =IF(W30<3000,"St","LT") -> LT | Y30: =VLOOKUP(RIGHT(L30,1),Sheet4!F:G,2,FALSE) -> Prime
A31: 5C03 | B31: PT. SETIA GUNA SELARAS | C31: X1B00AIA0120+57500 | D31: 1/2" | G31: 12,70 | H31: 1,20 | I31: 5.750,00mm | J31: 26 | K31: 50.882 | L31: 5261263F0A | N31: 0 | Q31: PT. SETIA GUNA SELARAS | R31: FAST | S31: PRIME | T31: 0 | V31: =VLOOKUP(MID(A31,2,1),Sheet4!A:B,2,FALSE) -> Gd.03 | W31: =IF(MID(C31,14,1)="A",RIGHT(C31,4)/1,IF(MID(C31,13,1)="+",RIGHT(C31,5)/10,IF(MID(C31,13,1)="-",RIGHT(C31,5)/1))) -> 5750 | X31: =IF(W31<3000,"St","LT") -> LT | Y31: =VLOOKUP(RIGHT(L31,1),Sheet4!F:G,2,FALSE) -> Prime
A32: 5C09 | B32: PT. SETIA GUNA SELARAS | C32: X1B00AIA0120+57500 | D32: 1/2" | G32: 12,70 | H32: 1,20 | I32: 5.750,00mm | J32: 55 | K32: 107.635 | L32: 5261258F0A | N32: 0 | Q32: PT. SETIA GUNA SELARAS | R32: FAST | S32: PRIME | T32: 0 | V32: =VLOOKUP(MID(A32,2,1),Sheet4!A:B,2,FALSE) -> Gd.03 | W32: =IF(MID(C32,14,1)="A",RIGHT(C32,4)/1,IF(MID(C32,13,1)="+",RIGHT(C32,5)/10,IF(MID(C32,13,1)="-",RIGHT(C32,5)/1))) -> 5750 | X32: =IF(W32<3000,"St","LT") -> LT | Y32: =VLOOKUP(RIGHT(L32,1),Sheet4!F:G,2,FALSE) -> Prime
A33: 5C09 | B33: PT. SETIA GUNA SELARAS | C33: X1B00AIA0120+57500 | D33: 1/2" | G33: 12,70 | H33: 1,20 | I33: 5.750,00mm | J33: 276 | K33: 540.132 | L33: 5261264F0A | N33: 0 | Q33: PT. SETIA GUNA SELARAS | R33: FAST | S33: PRIME | T33: 0 | V33: =VLOOKUP(MID(A33,2,1),Sheet4!A:B,2,FALSE) -> Gd.03 | W33: =IF(MID(C33,14,1)="A",RIGHT(C33,4)/1,IF(MID(C33,13,1)="+",RIGHT(C33,5)/10,IF(MID(C33,13,1)="-",RIGHT(C33,5)/1))) -> 5750 | X33: =IF(W33<3000,"St","LT") -> LT | Y33: =VLOOKUP(RIGHT(L33,1),Sheet4!F:G,2,FALSE) -> Prime
A34: 5C09 | B34: PT. SETIA GUNA SELARAS | C34: X1B00AIA0120+57500 | D34: 1/2" | G34: 12,70 | H34: 1,20 | I34: 5.750,00mm | J34: 418 | K34: 818.026 | L34: 5261614F0A | N34: 0 | Q34: PT. SETIA GUNA SELARAS | R34: FAST | S34: PRIME | T34: 0 | V34: =VLOOKUP(MID(A34,2,1),Sheet4!A:B,2,FALSE) -> Gd.03 | W34: =IF(MID(C34,14,1)="A",RIGHT(C34,4)/1,IF(MID(C34,13,1)="+",RIGHT(C34,5)/10,IF(MID(C34,13,1)="-",RIGHT(C34,5)/1))) -> 5750 | X34: =IF(W34<3000,"St","LT") -> LT | Y34: =VLOOKUP(RIGHT(L34,1),Sheet4!F:G,2,FALSE) -> Prime
A35: 5C09 | B35: PT. SETIA GUNA SELARAS | C35: X1B00AIA0120+57500 | D35: 1/2" | G35: 12,70 | H35: 1,20 | I35: 5.750,00mm | J35: 53 | K35: 103.721 | L35: 5261664F0A | N35: 0 | Q35: PT. SETIA GUNA SELARAS | R35: FAST | S35: PRIME | T35: 0 | V35: =VLOOKUP(MID(A35,2,1),Sheet4!A:B,2,FALSE) -> Gd.03 | W35: =IF(MID(C35,14,1)="A",RIGHT(C35,4)/1,IF(MID(C35,13,1)="+",RIGHT(C35,5)/10,IF(MID(C35,13,1)="-",RIGHT(C35,5)/1))) -> 5750 | X35: =IF(W35<3000,"St","LT") -> LT | Y35: =VLOOKUP(RIGHT(L35,1),Sheet4!F:G,2,FALSE) -> Prime
A36: 5D14 | B36: PT. CITRA ROBIN SARANA | C36: X1B00AIA0120+60600 | D36: 1/2" | G36: 12,70 | H36: 1,20 | I36: 6.060,00mm | J36: 234 | K36: 482.508 | L36: 5260750F0A | N36: 0 | Q36: PT. CITRA ROBIN SARANA | R36: FAST | S36: PRIME | T36: 0 | V36: =VLOOKUP(MID(A36,2,1),Sheet4!A:B,2,FALSE) -> Gd.04 | W36: =IF(MID(C36,14,1)="A",RIGHT(C36,4)/1,IF(MID(C36,13,1)="+",RIGHT(C36,5)/10,IF(MID(C36,13,1)="-",RIGHT(C36,5)/1))) -> 6060 | X36: =IF(W36<3000,"St","LT") -> LT | Y36: =VLOOKUP(RIGHT(L36,1),Sheet4!F:G,2,FALSE) -> Prime
A37: 5C10 | B37: PT. SETIA GUNA SEJATI | C37: X1B00AIA0150+30000 | D37: 1/2" | G37: 12,70 | H37: 1,50 | I37: 3.000,00mm | J37: 1302 | K37: 1618.386 | L37: 5261823F0A | N37: 0 | Q37: PT. SETIA GUNA SEJATI | R37: FAST | S37: PRIME | T37: 0 | V37: =VLOOKUP(MID(A37,2,1),Sheet4!A:B,2,FALSE) -> Gd.03 | W37: =IF(MID(C37,14,1)="A",RIGHT(C37,4)/1,IF(MID(C37,13,1)="+",RIGHT(C37,5)/10,IF(MID(C37,13,1)="-",RIGHT(C37,5)/1))) -> 3000 | X37: =IF(W37<3000,"St","LT") -> LT | Y37: =VLOOKUP(RIGHT(L37,1),Sheet4!F:G,2,FALSE) -> Prime
A38: 5D10 | B38: PT. SETIA GUNA SEJATI | C38: X1B00AIA0150+62300 | D38: 1/2" | G38: 12,70 | H38: 1,50 | I38: 6.230,00mm | J38: 212 | K38: 547.172 | L38: 5261816F0A | N38: 0 | Q38: PT. SETIA GUNA SEJATI | R38: FAST | S38: PRIME | T38: 0 | V38: =VLOOKUP(MID(A38,2,1),Sheet4!A:B,2,FALSE) -> Gd.04 | W38: =IF(MID(C38,14,1)="A",RIGHT(C38,4)/1,IF(MID(C38,13,1)="+",RIGHT(C38,5)/10,IF(MID(C38,13,1)="-",RIGHT(C38,5)/1))) -> 6230 | X38: =IF(W38<3000,"St","LT") -> LT | Y38: =VLOOKUP(RIGHT(L38,1),Sheet4!F:G,2,FALSE) -> Prime
... A40: 5D12 | B40: PT. SETIA GUNA SEJATI | C40: X1B00AIA0150+62300 | D40: 1/2" | G40: 12,70 | H40: 1,50 | I40: 6.230,00mm | J40: 52 | K40: 134.212 | L40: 5261815F0A | N40: 0 | Q40: PT. SETIA GUNA SEJATI | R40: FAST | S40: PRIME | T40: 0 | V40: =VLOOKUP(MID(A40,2,1),Sheet4!A:B,2,FALSE) -> Gd.04 | W40: =IF(MID(C40,14,1)="A",RIGHT(C40,4)/1,IF(MID(C40,13,1)="+",RIGHT(C40,5)/10,IF(MID(C40,13,1)="-",RIGHT(C40,5)/1))) -> 6230 | X40: =IF(W40<3000,"St","LT") -> LT | Y40: =VLOOKUP(RIGHT(L40,1),Sheet4!F:G,2,FALSE) -> Prime
A41: 5B09 | B41: PT. DELA CEMARA INDAH | C41: X1B00AIL0150+42180 | G41: 13,80 | H41: 1,50 | I41: 4.218,00mm | J41: 34 | K41: 65.246 | L41: 5261083B0A | N41: 0 | Q41: PT. DELA CEMARA INDAH | R41: FAST | S41: PRIME | T41: 0 | V41: =VLOOKUP(MID(A41,2,1),Sheet4!A:B,2,FALSE) -> Gd.02 | W41: =IF(MID(C41,14,1)="A",RIGHT(C41,4)/1,IF(MID(C41,13,1)="+",RIGHT(C41,5)/10,IF(MID(C41,13,1)="-",RIGHT(C41,5)/1))) -> 4218 | X41: =IF(W41<3000,"St","LT") -> LT | Y41: =VLOOKUP(RIGHT(L41,1),Sheet4!F:G,2,FALSE) -> Prime
A42: 5C08 | B42: PT. DELA CEMARA INDAH | C42: X1B00AIL0150+44200 | G42: 13,80 | H42: 1,50 | I42: 4.420,00mm | J42: 34 | K42: 68.374 | L42: 5250433B0A | N42: 0 | Q42: PT. DELA CEMARA INDAH | R42: FAST | S42: PRIME | T42: 0 | V42: =VLOOKUP(MID(A42,2,1),Sheet4!A:B,2,FALSE) -> Gd.03 | W42: =IF(MID(C42,14,1)="A",RIGHT(C42,4)/1,IF(MID(C42,13,1)="+",RIGHT(C42,5)/10,IF(MID(C42,13,1)="-",RIGHT(C42,5)/1))) -> 4420 | X42: =IF(W42<3000,"St","LT") -> LT | Y42: =VLOOKUP(RIGHT(L42,1),Sheet4!F:G,2,FALSE) -> Prime
A43: 5D19 | B43: PT. RINNAI INDONESIA | C43: X1B00AIL0190+58500 | G43: 13,80 | H43: 1,90 | I43: 5.850,00mm | J43: 172 | K43: 561.064 | L43: 5260741B0A | N43: 0 | Q43: PT. RINNAI INDONESIA | R43: FAST | S43: PRIME | T43: 0 | V43: =VLOOKUP(MID(A43,2,1),Sheet4!A:B,2,FALSE) -> Gd.04 | W43: =IF(MID(C43,14,1)="A",RIGHT(C43,4)/1,IF(MID(C43,13,1)="+",RIGHT(C43,5)/10,IF(MID(C43,13,1)="-",RIGHT(C43,5)/1))) -> 5850 | X43: =IF(W43<3000,"St","LT") -> LT | Y43: =VLOOKUP(RIGHT(L43,1),Sheet4!F:G,2,FALSE) -> Prime
A44: 5D19 | B44: PT. RINNAI INDONESIA | C44: X1B00AIL0190+58500 | G44: 13,80 | H44: 1,90 | I44: 5.850,00mm | J44: 70 | K44: 228.34 | L44: 5261065B0A | N44: 0 | Q44: PT. RINNAI INDONESIA | R44: FAST | S44: PRIME | T44: 0 | V44: =VLOOKUP(MID(A44,2,1),Sheet4!A:B,2,FALSE) -> Gd.04 | W44: =IF(MID(C44,14,1)="A",RIGHT(C44,4)/1,IF(MID(C44,13,1)="+",RIGHT(C44,5)/10,IF(MID(C44,13,1)="-",RIGHT(C44,5)/1))) -> 5850 | X44: =IF(W44<3000,"St","LT") -> LT | Y44: =VLOOKUP(RIGHT(L44,1),Sheet4!F:G,2,FALSE) -> Prime
A45: 5D12 | B45: TRAIL KBU | C45: X1B00AIL0220+60000 | G45: 13,80 | H45: 2,20 | I45: 6.000,00mm | J45: 141 | K45: 532.416 | L45: 5250467B0A | N45: 0 | Q45: TRAIL KBU | R45: FAST | S45: PRIME | T45: 0 | V45: =VLOOKUP(MID(A45,2,1),Sheet4!A:B,2,FALSE) -> Gd.04 | W45: =IF(MID(C45,14,1)="A",RIGHT(C45,4)/1,IF(MID(C45,13,1)="+",RIGHT(C45,5)/10,IF(MID(C45,13,1)="-",RIGHT(C45,5)/1))) -> 6000 | X45: =IF(W45<3000,"St","LT") -> LT | Y45: =VLOOKUP(RIGHT(L45,1),Sheet4!F:G,2,FALSE) -> Prime
A46: 5B04 | C46: X1B00AIN0040+57000 | G46: 14,00 | H46: 0,40 | I46: 5.700,00mm | J46: 124 | K46: 94.86 | L46: 5251222B0A | N46: 0 | R46: FAST | S46: PRIME | T46: 0 | V46: =VLOOKUP(MID(A46,2,1),Sheet4!A:B,2,FALSE) -> Gd.02 | W46: =IF(MID(C46,14,1)="A",RIGHT(C46,4)/1,IF(MID(C46,13,1)="+",RIGHT(C46,5)/10,IF(MID(C46,13,1)="-",RIGHT(C46,5)/1))) -> 5700 | X46: =IF(W46<3000,"St","LT") -> LT | Y46: =VLOOKUP(RIGHT(L46,1),Sheet4!F:G,2,FALSE) -> Prime
A47: 5B04 | C47: X1B00AIN0040+59600 | G47: 14,00 | H47: 0,40 | I47: 5.960,00mm | J47: 83 | K47: 66.4 | L47: 5251222B0A | N47: 0 | R47: FAST | S47: PRIME | T47: 0 | V47: =VLOOKUP(MID(A47,2,1),Sheet4!A:B,2,FALSE) -> Gd.02 | W47: =IF(MID(C47,14,1)="A",RIGHT(C47,4)/1,IF(MID(C47,13,1)="+",RIGHT(C47,5)/10,IF(MID(C47,13,1)="-",RIGHT(C47,5)/1))) -> 5960 | X47: =IF(W47<3000,"St","LT") -> LT | Y47: =VLOOKUP(RIGHT(L47,1),Sheet4!F:G,2,FALSE) -> Prime
A48: 5B07 | B48: PT. SETIA GUNA SELARAS | C48: X1B00AIN0150+60000 | G48: 14,00 | H48: 1,50 | I48: 6.000,00mm | J48: 154 | K48: 427.196 | L48: 5261820B0A | N48: 0 | Q48: PT. SETIA GUNA SELARAS | R48: FAST | S48: PRIME | T48: 0 | V48: =VLOOKUP(MID(A48,2,1),Sheet4!A:B,2,FALSE) -> Gd.02 | W48: =IF(MID(C48,14,1)="A",RIGHT(C48,4)/1,IF(MID(C48,13,1)="+",RIGHT(C48,5)/10,IF(MID(C48,13,1)="-",RIGHT(C48,5)/1))) -> 6000 | X48: =IF(W48<3000,"St","LT") -> LT | Y48: =VLOOKUP(RIGHT(L48,1),Sheet4!F:G,2,FALSE) -> Prime
...

Sheet MP repair
A1: No | B1: Tanggal | C1: Jumlah Operator | D1: Shift | E1: Gudang
A2: 1 | B2: 46266 | C2: 3 | D2: 1 | E2: Gd 5
A3: 2 | B3: 46266 | C3: 2 | D3: 1 | E3: Gd 1
A4: 3 | B4: 46266 | C4: 7 | D4: 1 | E4: Gd 13
A5: 4 | B5: 46267 | C5: 4 | D5: 1 | E5: Gd 5
A6: 5 | B6: 46267 | C6: 4 | D6: 1 | E6: Gd 1
A7: 6 | B7: 46267 | C7: 5 | D7: 1 | E7: Gd 13
A8: 7 | B8: 46268 | C8: 4 | D8: 1 | E8: Gd 5
A9: 8 | B9: 46268 | C9: 2 | D9: 1 | E9: Gd 1
A10: 9 | B10: 46268 | C10: 6 | D10: 1 | E10: Gd 13
A11: 10 | B11: 46269 | C11: 4 | D11: 1 | E11: Gd 5
A12: 11 | B12: 46269 | C12: 2 | D12: 1 | E12: Gd 1
A13: 12 | B13: 46269 | C13: 4 | D13: 1 | E13: Gd 13
... A16: 15 | B16: 46270 | C16: 5 | D16: 1 | E16: Gd 13

Sheet Sheet4
A1: Kode Sloc | B1: Gudang | D1: Range Coil/Strip | E1: Coil/Strip | F1: Kode Batch | G1: Grade
A2: A | B2: Gd.01 | D2: C1 Over 500mm | E2: 1. Coil | F2: 0 | G2: Prime
A3: B | B3: Gd.02 | D3: C2 1-500mm | E3: 2. Strip | F3: 3 | G3: Prime
A4: C | B4: Gd.03 | D4: C2 Over 500mm | E4: 1. Coil | F4: 5 | G4: Prime
A5: D | B5: Gd.04 | D5: C3 Over 500mm | E5: 3. Plat | F5: A | G5: Prime
A6: E | B6: Gd.05 | D6: J1 1-500mm | E6: 2. Strip | F6: C | G6: Grd C
A7: F | B7: Gd.06 | D7: J2 1-500mm | E7: 2. Strip | F7: E | G7: Grd E
A8: G | B8: Gd.08 | D8: J1 Over 500mm | E8: 1. Coil | F8: G | G8: Prime
A9: H | B9: Gd.09 | F9: O | G9: Prime
A10: I | B10: - | F10: B | G10: DG
A11: J | B11: Gd.10
A12: K | B12: Gd.11
A13: L | B13: Gd.12
A14: M | B14: Gd.13
A15: N | B15: Gd.14
A16: O | B16: -
